Workbook

Sheet Read Me & Glossary
A1: READ ME — how this model works
A2: Purpose | B2: Investor-facing model to sell 50% of a 3-property (+ tours) portfolio into NewCo. Shows independent property valuation, after-tax cash returns, total return and a leverage/growth path. DRAFT — accountant/attorney sign-off pending.
A3: Structure | B3: NewCo owns 100% of the included properties. The incoming Property Partner can hold a different % per property via Control share-offer inputs. Buy-in is consideration paid to the current owner (share sale), not retained as working capital in NewCo.
A4: How to use | B4: Edit only the shaded (yellow) input cells on the Control sheet. Every other sheet recalculates. Open in Excel or Google Sheets so formulas compute.
A5: Sheets | B5: Control (inputs) · 3 property P&Ls · Portfolio NewCo (consolidated) · Valuation (independent) · Investor KPIs · Property KPIs · Leverage & Growth · Change Log.
A7: TERMINOLOGY (SA hospitality standard):
A8: Unit | B8: One lettable villa/apartment (African Sky Villa, Remington, Winchester). Whole-unit lets, not per-room.
A9: Available unit-night | B9: One unit available for one night. Units × 365 = available unit-nights per year.
A10: Occupied unit-night | B10: One unit actually let for one night. Occupancy % = occupied ÷ available.
A11: ADR | B11: Average Daily Rate — the gross nightly rate per unit (base covers 2 guests; extra guests add per-guest).
A12: Guest-night | B12: One guest staying one night = occupied unit-nights × guests per unit. Drives meals.
A13: Meal cover | B13: One guest taking meals on one night. 75% of guest-nights take both breakfast + dinner.
A14: NOI | B14: Net Operating Income — revenue less operating expenses (incl. FF&E reserve), before tax and finance. Basis for income valuation.
A15: Cap rate | B15: Capitalisation rate — NOI ÷ property value. Lower cap rate = higher value. Used for residential income valuation.
A16: MOIC / IRR | B16: MOIC = money multiple (total received ÷ invested). IRR = annualised return accounting for timing.
A17: VALUATION METHOD | B17: Beachside & Menlyn are valued by income capitalisation (NOI ÷ market cap rate), which corroborates their cost basis. African Sky is valued on comparable/cost because its income is largely OPERATING (holiday-let + F&B + tours) — capitalising that at a property cap rate would massively overstate 3 villas. Adopted NAV is deliberately conservative; the income approach sits above it.
A18: OPEN FLAGS (gated) | B18: • VAT: combined revenue is over the R1m compulsory-registration threshold — short-term accommodation is taxable, long-term residential exempt (mixed supply). Default keeps the gross basis; confirm with the accountant. • Transfer of properties into NewCo triggers transfer duty / VAT / CGT, and a s42 asset-for-share roll-over carries an 18-month de-grouping clawback if 50% is sold at/near formation — attorney + accountant. • Selling 50% equity may engage Companies Act offer-to-public / FAIS rules. • Cap rates and the African Sky comparable value are assumptions to confirm with a registered valuer. • Winchester is not built — its revenue is phased from its online year and its R500k build is funded from NewCo cash.
A19: Status | B19: DRAFT · unaudited · ZAR · rebuilt 2026-07-10. Not an offer to the public; subject to MOI/shareholders agreement and professional sign-off. Nothing here is legal, tax or investment advice.
A20: TOURS (v3) | B20: African Sky tour income and supplier cost are now driven by the 'ASKY Tours Calcs' sheet — 14 experiences (safaris, day tours, river adventures, transfers) each with per-pax retail (fixed from the live site), supplier cost and take-up. The Control tour cells link to its totals (revenue O27, cost P27); edit tours on that sheet.

Sheet Key Assumptions Sources
A1: KEY ASSUMPTIONS & SOURCES
A2: Plain-English source sheet for proposal review. All model items are live linked where relevant.
A4: Category | B4: Assumption | C4: Value | D4: Source / explanation
A5: Scenario | B5: African Sky partner share % | C5: 0.5 | D5: 0% excludes property; >0% includes at selected share
A6: Scenario | B6: Winchester expansion option | C6: N | D6: Y/N; only active if African Sky share > 0%
A7: Scenario | B7: Beachside partner share % | C7: 0.5 | D7: 0% excludes property; >0% includes at selected share
A8: Scenario | B8: Menlyn partner share % | C8: 0.5 | D8: 0% excludes property; >0% includes at selected share
A9: Guests | B9: ASV avg guests per occupied unit-night | C9: 2.8 | D9: Control!B31
A10: Pricing | B10: ASV base ADR incl. 2 guests | C10: 4500 | D10: Control!B28
A11: Pricing | B11: ASV extra guest rate | C11: 1000 | D11: Control!B29
A12: Pricing | B12: Remington base ADR incl. 2 guests | C12: =Control!$B$32 -> 3700 | D12: Control!B32
A13: Pricing | B13: Remington extra guest rate | C13: =Control!$B$33 -> 750 | D13: Control!B33
A14: Tours | B14: Tour revenue Year 1 | C14: 2071762.4 | D14: Linked from ASKY Tours Calcs totals
A15: Tours | B15: Tour supplier cost Year 1 | C15: 1512882.8 | D15: Linked from ASKY Tours Calcs totals
A16: Stay duration | B16: ASV avg nights / booking | C16: 0 | D16: Realised booking analysis in ASKY Stay Calc
A17: Stay duration | B17: Remington avg nights / booking | C17: 0 | D17: Realised booking analysis in ASKY Stay Calc
A18: Valuation | B18: Adopted property value | C18: 12800000 | D18: Valuation!F9
A19: Valuation | B19: Partner NAV today | C19: 6400000 | D19: Valuation!F10
A20: Exit | B20: Property value growth p.a. | C20: 0.05 | D20: Control!B68 linked to Control!B74
A21: Tax / legal | B21: Open flags | C21: See Read Me & Glossary!B18 | D21: Accountant/attorney sign-off required
A22: Optional asset | B22: Winchester development expansion toggle | C22: N | D22: Y includes Winchester revenue, build capex and value; N excludes it. Only active if African Sky toggle is Y.

Sheet Control
A1: CONTROL — edit only the shaded (yellow) input cells
A2: ZAR · DRAFT · all sheets link here. Terminology follows SA hospitality/property convention — see 'Read Me & Glossary'.
A4: 0 · PARTNER SHARE OFFER | B4: Partner Offer Prop % | C4: Distribution allocation % | E4: INVESTOR KPI SNAPSHOT — ACTIVE PORTFOLIO
A5: African Sky partner share % | B5: 0.5 | C5: =B5 -> 0.5 | E5: KPI | F5: Value | G5: What it shows
A6: Winchester expansion? (Y/N; active if African Sky share > 0%) | B6: N | E6: =_xlfn.TEXTJOIN(", ",TRUE,IF($B$5>0,"African Sky",""),IF(AND($B$5>0,$B$6="Y"),"Winchester expansion",""),IF($B$7>0,"Beachside",""),IF($B$8>0,"Menlyn","")) -> African Sky, Beachside, Menlyn | G6: Properties with share % > 0 are included; Winchester is separate option
A7: Beachside partner share % | B7: 0.5 | C7: =B7 -> 0.5 | E7: Active portfolio value | F7: =Valuation!$F$9 -> 12900000 | G7: 100% adopted value of active properties
A8: Menlyn partner share % | B8: 0.5 | C8: =B8 -> 0.5 | E8: Partner buy-in | F8: =Control!$B$15 -> 6400000 | G8: Cash consideration based on active properties and property-specific partner %
E9: Partner NAV today | F9: =Valuation!$F$10 -> 6450000 | G9: Partner NAV using property-specific partner % by property
A10: 1 · DEAL & STRUCTURE | E10: Offer vs NAV | F10: =IFERROR(Control!$B$15/Valuation!$F$10,"") -> 0.99224806 | G10: 1.0x = buy-in equals NAV
A11: Reference % for listed buy-in pricing | B11: 0.5 | E11: Year 1 partner distribution | F11: ='Portfolio NewCo'!B16 -> 952520.4 | G11: Projected first-year cash distribution using Control distribution allocation %
A12: African Sky — buy-in at reference % (ZAR) | B12: 3000000 | E12: Year 1 cash yield | F12: =IFERROR('Portfolio NewCo'!B16/Control!$B$15,"") -> 0.14883131 | G12: Year 1 distribution ÷ partner buy-in
A13: Beachside — buy-in at reference % (ZAR) | B13: 2000000 | E13: Cash payback year | F13: ='INV - Investor KPIs'!B25 -> 6 | G13: Year cumulative distributions recover buy-in
A14: Menlyn — buy-in at reference % (ZAR) | B14: 1400000 | E14: 5Y Total Partner Distributions | F14: ='INV - Investor KPIs'!G7 -> 5263276.5 | G14: Cumulative partner distributions received through Year 5
A15: Total active partner buy-in (share-offer %) | B15: =IF($B$5>0,$B$12/$B$11*$B$5,0)+IF($B$7>0,$B$13/$B$11*$B$7,0)+IF($B$8>0,$B$14/$B$11*$B$8,0) -> 6400000 | E15: 5Y Total Partner Value if Exit in Year 5 | F15: ='INV - Investor KPIs'!G12 -> 13001372 | G15: Cumulative distributions + exit NAV — Total Partner Value if Exit in Year 5
A16: 2 · FORECAST DRIVERS | E16: 5Y Total IRR | F16: ='INV - Investor KPIs'!C18 -> 0.19036144 | G16: Includes cash distributions + exit NAV
A17: Room-rate (ADR) escalation p.a. | B17: 0.05 | E17: 5Y Total MOIC | F17: ='INV - Investor KPIs'!C20 -> 2.0314643 | G17: Total value received ÷ buy-in
A18: Expense inflation p.a. | B18: 0.05 | E18: 10Y Total Partner Distributions | F18: ='INV - Investor KPIs'!L7 -> 11980699 | G18: Cumulative partner distributions received through Year 10
A19: Occupancy — short-let units (%) — DEPRECATED: replaced by per-villa occupancy (B30 / B34 / B37) | B19: 0.75 | E19: 10Y Total Partner Value if Exit in Year 10 | F19: ='INV - Investor KPIs'!L12 -> 21856687 | G19: Cumulative distributions + exit NAV — Total Partner Value if Exit in Year 10
A20: Available nights per year | B20: 365 | E20: 10Y Total IRR | F20: ='INV - Investor KPIs'!D18 -> 0.19595828 | G20: Includes cash distributions + exit NAV
A21: Model horizon (years) — DISPLAY MEMO ONLY: projection is fixed at 20 years | B21: 20 | E21: 10Y Total MOIC | F21: ='INV - Investor KPIs'!D20 -> 3.4151074 | G21: Total value received ÷ buy-in
A22: 3 · TAX, VAT & RESERVES | E22: 15Y Total Partner Distributions | F22: ='INV - Investor KPIs'!Q7 -> 20554022 | G22: Cumulative partner distributions received through Year 15
A23: Corporate income tax rate | B23: 0.27 | E23: 15Y Total Partner Value if Exit in Year 15 | F23: ='INV - Investor KPIs'!Q12 -> 33158564 | G23: Cumulative distributions + exit NAV — Total Partner Value if Exit in Year 15
A24: Apply output VAT to short-let accommodation? (1=Yes/0=No) — PLACEHOLDER: VAT not yet wired; gated to accountant | B24: 0 | E24: 15Y Total IRR | F24: ='INV - Investor KPIs'!E18 -> 0.19757586 | G24: Includes cash distributions + exit NAV
A25: VAT rate — PLACEHOLDER: not yet wired | B25: 0.15 | E25: 15Y Total MOIC | F25: ='INV - Investor KPIs'!E20 -> 5.1810255 | G25: Total value received ÷ buy-in
A26: FF&E / capex reserve (% of accommodation revenue) | B26: 0.04 | E26: 20Y Total Partner Distributions | F26: ='INV - Investor KPIs'!V7 -> 31495996 | G26: Cumulative partner distributions received through Year 20
A27: 4 · AFRICAN SKY VILLAS — 3 units + meals + tours | E27: 20Y Total Partner Value if Exit in Year 20 | F27: ='INV - Investor KPIs'!V12 -> 47582940 | G27: Cumulative distributions + exit NAV — Total Partner Value if Exit in Year 20
A28: African Sky Villa — ADR incl. 2 guests (ZAR/night) | B28: 4500 | E28: 20Y Total IRR | F28: ='INV - Investor KPIs'!F18 -> 0.19823225 | G28: Includes cash distributions + exit NAV
A29: African Sky Villa — extra-guest rate (ZAR/guest/night) | B29: 1000 | E29: 20Y Total MOIC | F29: ='INV - Investor KPIs'!F20 -> 7.4348343 | G29: Total value received ÷ buy-in
A30: African Sky Villa — avg annual nights booked (%) | B30: ='ASKY Bookings'!C390 -> 0.68175583
A31: African Sky Villa — avg guests per occupied unit-night | B31: ='ASKY Bookings'!C409 -> 2.750503
A32: Remington Villa — ADR incl. 2 guests (ZAR/night) | B32: 3700
A33: Remington Villa — extra-guest rate (ZAR/guest/night) | B33: 750
A34: Remington Villa — avg annual nights booked (%) | B34: ='ASKY Bookings'!D390 -> 0.62328767
A35: Remington Villa — avg guests per occupied unit-night | B35: ='ASKY Bookings'!D409 -> 2.6879121
A36: Winchester (planned) — ADR, sleeps 2 (ZAR/night) | B36: 3500
A37: Winchester — avg annual nights booked (%) | B37: 0.52
A38: Winchester — avg guests per occupied unit-night | B38: 2
A39: Winchester — online from year | B39: 2
A40: Winchester — construction cost (ZAR, one-off) | B40: 500000
A41: Meal take-up — guests taking both meals (%) | B41: 0.75
...

Sheet African Sky P&L
A1: AFRICAN SKY VILLAS — P&L (annual, 20-year)
A2: 3 units (African Sky Villa · Remington · Winchester) + meals + tours. Winchester phases in from its online year. After FF&E reserve, after tax.
A4: Year | C4: 1 | D4: 2 | E4: 3 | F4: 4 | G4: 5 | H4: 6 | I4: 7 | J4: 8 | K4: 9 | L4: 10 | M4: 11 | N4: 12 | O4: 13 | P4: 14 | Q4: 15 | R4: 16 | S4: 17 | T4: 18 | U4: 19 | V4: 20
A6: Occupied unit-nights / unit | C6: =IF(Control!$B$5>0,Control!$B$20*(Control!$B$30+Control!$B$34+IF(Control!$B$6="Y",Control!$B$37,0))/(2+IF(Control!$B$6="Y",1,0)),0) -> 238.17044 | D6: =IF(Control!$B$5>0,Control!$B$20*(Control!$B$30+Control!$B$34+IF(Control!$B$6="Y",Control!$B$37,0))/(2+IF(Control!$B$6="Y",1,0)),0) -> 238.17044 | E6: =IF(Control!$B$5>0,Control!$B$20*(Control!$B$30+Control!$B$34+IF(Control!$B$6="Y",Control!$B$37,0))/(2+IF(Control!$B$6="Y",1,0)),0) -> 238.17044 | F6: =IF(Control!$B$5>0,Control!$B$20*(Control!$B$30+Control!$B$34+IF(Control!$B$6="Y",Control!$B$37,0))/(2+IF(Control!$B$6="Y",1,0)),0) -> 238.17044 | G6: =IF(Control!$B$5>0,Control!$B$20*(Control!$B$30+Control!$B$34+IF(Control!$B$6="Y",Control!$B$37,0))/(2+IF(Control!$B$6="Y",1,0)),0) -> 238.17044 | H6: =IF(Control!$B$5>0,Control!$B$20*(Control!$B$30+Control!$B$34+IF(Control!$B$6="Y",Control!$B$37,0))/(2+IF(Control!$B$6="Y",1,0)),0) -> 238.17044 | I6: =IF(Control!$B$5>0,Control!$B$20*(Control!$B$30+Control!$B$34+IF(Control!$B$6="Y",Control!$B$37,0))/(2+IF(Control!$B$6="Y",1,0)),0) -> 238.17044 | J6: =IF(Control!$B$5>0,Control!$B$20*(Control!$B$30+Control!$B$34+IF(Control!$B$6="Y",Control!$B$37,0))/(2+IF(Control!$B$6="Y",1,0)),0) -> 238.17044 | ... V6: =IF(Control!$B$5>0,Control!$B$20*(Control!$B$30+Control!$B$34+IF(Control!$B$6="Y",Control!$B$37,0))/(2+IF(Control!$B$6="Y",1,0)),0) -> 238.17044
A7: African Sky Villa — accommodation | C7: =IF(Control!$B$5>0,(Control!$B$20*Control!$B$30)*(Control!$B$28+Control!$B$29*MAX(0,Control!$B$31-2))*POWER(1+Control!$B$17,C$4-1),0) -> 1306539.8 | D7: =IF(Control!$B$5>0,(Control!$B$20*Control!$B$30)*(Control!$B$28+Control!$B$29*MAX(0,Control!$B$31-2))*POWER(1+Control!$B$17,D$4-1),0) -> 1371866.8 | E7: =IF(Control!$B$5>0,(Control!$B$20*Control!$B$30)*(Control!$B$28+Control!$B$29*MAX(0,Control!$B$31-2))*POWER(1+Control!$B$17,E$4-1),0) -> 1440460.1 | F7: =IF(Control!$B$5>0,(Control!$B$20*Control!$B$30)*(Control!$B$28+Control!$B$29*MAX(0,Control!$B$31-2))*POWER(1+Control!$B$17,F$4-1),0) -> 1512483.1 | G7: =IF(Control!$B$5>0,(Control!$B$20*Control!$B$30)*(Control!$B$28+Control!$B$29*MAX(0,Control!$B$31-2))*POWER(1+Control!$B$17,G$4-1),0) -> 1588107.3 | H7: =IF(Control!$B$5>0,(Control!$B$20*Control!$B$30)*(Control!$B$28+Control!$B$29*MAX(0,Control!$B$31-2))*POWER(1+Control!$B$17,H$4-1),0) -> 1667512.6 | I7: =IF(Control!$B$5>0,(Control!$B$20*Control!$B$30)*(Control!$B$28+Control!$B$29*MAX(0,Control!$B$31-2))*POWER(1+Control!$B$17,I$4-1),0) -> 1750888.3 | J7: =IF(Control!$B$5>0,(Control!$B$20*Control!$B$30)*(Control!$B$28+Control!$B$29*MAX(0,Control!$B$31-2))*POWER(1+Control!$B$17,J$4-1),0) -> 1838432.7 | ... V7: =IF(Control!$B$5>0,(Control!$B$20*Control!$B$30)*(Control!$B$28+Control!$B$29*MAX(0,Control!$B$31-2))*POWER(1+Control!$B$17,V$4-1),0) -> 3301561
A8: Remington Villa — accommodation | C8: =IF(Control!$B$5>0,(Control!$B$20*Control!$B$34)*(Control!$B$32+Control!$B$33*MAX(0,Control!$B$35-2))*POWER(1+Control!$B$17,C$4-1),0) -> 959125 | D8: =IF(Control!$B$5>0,(Control!$B$20*Control!$B$34)*(Control!$B$32+Control!$B$33*MAX(0,Control!$B$35-2))*POWER(1+Control!$B$17,D$4-1),0) -> 1007081.3 | E8: =IF(Control!$B$5>0,(Control!$B$20*Control!$B$34)*(Control!$B$32+Control!$B$33*MAX(0,Control!$B$35-2))*POWER(1+Control!$B$17,E$4-1),0) -> 1057435.3 | F8: =IF(Control!$B$5>0,(Control!$B$20*Control!$B$34)*(Control!$B$32+Control!$B$33*MAX(0,Control!$B$35-2))*POWER(1+Control!$B$17,F$4-1),0) -> 1110307.1 | G8: =IF(Control!$B$5>0,(Control!$B$20*Control!$B$34)*(Control!$B$32+Control!$B$33*MAX(0,Control!$B$35-2))*POWER(1+Control!$B$17,G$4-1),0) -> 1165822.4 | H8: =IF(Control!$B$5>0,(Control!$B$20*Control!$B$34)*(Control!$B$32+Control!$B$33*MAX(0,Control!$B$35-2))*POWER(1+Control!$B$17,H$4-1),0) -> 1224113.6 | I8: =IF(Control!$B$5>0,(Control!$B$20*Control!$B$34)*(Control!$B$32+Control!$B$33*MAX(0,Control!$B$35-2))*POWER(1+Control!$B$17,I$4-1),0) -> 1285319.2 | J8: =IF(Control!$B$5>0,(Control!$B$20*Control!$B$34)*(Control!$B$32+Control!$B$33*MAX(0,Control!$B$35-2))*POWER(1+Control!$B$17,J$4-1),0) -> 1349585.2 | ... V8: =IF(Control!$B$5>0,(Control!$B$20*Control!$B$34)*(Control!$B$32+Control!$B$33*MAX(0,Control!$B$35-2))*POWER(1+Control!$B$17,V$4-1),0) -> 2423661.1
A9: Winchester — accommodation | C9: =IF(AND(Control!$B$5>0,Control!$B$6="Y",C$4>=Control!$B$39),(Control!$B$20*Control!$B$37)*Control!$B$36*POWER(1+Control!$B$17,C$4-1),0) -> 0 | D9: =IF(AND(Control!$B$5>0,Control!$B$6="Y",D$4>=Control!$B$39),(Control!$B$20*Control!$B$37)*Control!$B$36*POWER(1+Control!$B$17,D$4-1),0) -> 0 | E9: =IF(AND(Control!$B$5>0,Control!$B$6="Y",E$4>=Control!$B$39),(Control!$B$20*Control!$B$37)*Control!$B$36*POWER(1+Control!$B$17,E$4-1),0) -> 0 | F9: =IF(AND(Control!$B$5>0,Control!$B$6="Y",F$4>=Control!$B$39),(Control!$B$20*Control!$B$37)*Control!$B$36*POWER(1+Control!$B$17,F$4-1),0) -> 0 | G9: =IF(AND(Control!$B$5>0,Control!$B$6="Y",G$4>=Control!$B$39),(Control!$B$20*Control!$B$37)*Control!$B$36*POWER(1+Control!$B$17,G$4-1),0) -> 0 | H9: =IF(AND(Control!$B$5>0,Control!$B$6="Y",H$4>=Control!$B$39),(Control!$B$20*Control!$B$37)*Control!$B$36*POWER(1+Control!$B$17,H$4-1),0) -> 0 | I9: =IF(AND(Control!$B$5>0,Control!$B$6="Y",I$4>=Control!$B$39),(Control!$B$20*Control!$B$37)*Control!$B$36*POWER(1+Control!$B$17,I$4-1),0) -> 0 | J9: =IF(AND(Control!$B$5>0,Control!$B$6="Y",J$4>=Control!$B$39),(Control!$B$20*Control!$B$37)*Control!$B$36*POWER(1+Control!$B$17,J$4-1),0) -> 0 | ... V9: =IF(AND(Control!$B$5>0,Control!$B$6="Y",V$4>=Control!$B$39),(Control!$B$20*Control!$B$37)*Control!$B$36*POWER(1+Control!$B$17,V$4-1),0) -> 0
A10: Accommodation revenue — all units | C10: =SUM(C7:C9) -> 2265664.8 | D10: =SUM(D7:D9) -> 2378948 | E10: =SUM(E7:E9) -> 2497895.4 | F10: =SUM(F7:F9) -> 2622790.2 | G10: =SUM(G7:G9) -> 2753929.7 | H10: =SUM(H7:H9) -> 2891626.2 | I10: =SUM(I7:I9) -> 3036207.5 | J10: =SUM(J7:J9) -> 3188017.9 | ... V10: =SUM(V7:V9) -> 5725222.1
A11: Guest-nights (meal base) | C11: =IF(Control!$B$5>0,Control!$B$20*(Control!$B$30*Control!$B$31+Control!$B$34*Control!$B$35+IF(AND(Control!$B$6="Y",C$4>=Control!$B$39),Control!$B$37*Control!$B$38,0)),0) -> 1295.9376 | D11: =IF(Control!$B$5>0,Control!$B$20*(Control!$B$30*Control!$B$31+Control!$B$34*Control!$B$35+IF(AND(Control!$B$6="Y",D$4>=Control!$B$39),Control!$B$37*Control!$B$38,0)),0) -> 1295.9376 | E11: =IF(Control!$B$5>0,Control!$B$20*(Control!$B$30*Control!$B$31+Control!$B$34*Control!$B$35+IF(AND(Control!$B$6="Y",E$4>=Control!$B$39),Control!$B$37*Control!$B$38,0)),0) -> 1295.9376 | F11: =IF(Control!$B$5>0,Control!$B$20*(Control!$B$30*Control!$B$31+Control!$B$34*Control!$B$35+IF(AND(Control!$B$6="Y",F$4>=Control!$B$39),Control!$B$37*Control!$B$38,0)),0) -> 1295.9376 | G11: =IF(Control!$B$5>0,Control!$B$20*(Control!$B$30*Control!$B$31+Control!$B$34*Control!$B$35+IF(AND(Control!$B$6="Y",G$4>=Control!$B$39),Control!$B$37*Control!$B$38,0)),0) -> 1295.9376 | H11: =IF(Control!$B$5>0,Control!$B$20*(Control!$B$30*Control!$B$31+Control!$B$34*Control!$B$35+IF(AND(Control!$B$6="Y",H$4>=Control!$B$39),Control!$B$37*Control!$B$38,0)),0) -> 1295.9376 | I11: =IF(Control!$B$5>0,Control!$B$20*(Control!$B$30*Control!$B$31+Control!$B$34*Control!$B$35+IF(AND(Control!$B$6="Y",I$4>=Control!$B$39),Control!$B$37*Control!$B$38,0)),0) -> 1295.9376 | J11: =IF(Control!$B$5>0,Control!$B$20*(Control!$B$30*Control!$B$31+Control!$B$34*Control!$B$35+IF(AND(Control!$B$6="Y",J$4>=Control!$B$39),Control!$B$37*Control!$B$38,0)),0) -> 1295.9376 | ... V11: =IF(Control!$B$5>0,Control!$B$20*(Control!$B$30*Control!$B$31+Control!$B$34*Control!$B$35+IF(AND(Control!$B$6="Y",V$4>=Control!$B$39),Control!$B$37*Control!$B$38,0)),0) -> 1295.9376
A12: Meal covers — both meals taken | C12: =C11*Control!$B$41 -> 971.95319 | D12: =D11*Control!$B$41 -> 971.95319 | E12: =E11*Control!$B$41 -> 971.95319 | F12: =F11*Control!$B$41 -> 971.95319 | G12: =G11*Control!$B$41 -> 971.95319 | H12: =H11*Control!$B$41 -> 971.95319 | I12: =I11*Control!$B$41 -> 971.95319 | J12: =J11*Control!$B$41 -> 971.95319 | ... V12: =V11*Control!$B$41 -> 971.95319
A13: Meals income (breakfast + dinner) | C13: =C12*(Control!$B$42+Control!$B$44)*POWER(1+Control!$B$17,C$4-1) -> 510275.42 | D13: =D12*(Control!$B$42+Control!$B$44)*POWER(1+Control!$B$17,D$4-1) -> 535789.2 | E13: =E12*(Control!$B$42+Control!$B$44)*POWER(1+Control!$B$17,E$4-1) -> 562578.66 | F13: =F12*(Control!$B$42+Control!$B$44)*POWER(1+Control!$B$17,F$4-1) -> 590707.59 | G13: =G12*(Control!$B$42+Control!$B$44)*POWER(1+Control!$B$17,G$4-1) -> 620242.97 | H13: =H12*(Control!$B$42+Control!$B$44)*POWER(1+Control!$B$17,H$4-1) -> 651255.12 | I13: =I12*(Control!$B$42+Control!$B$44)*POWER(1+Control!$B$17,I$4-1) -> 683817.87 | J13: =J12*(Control!$B$42+Control!$B$44)*POWER(1+Control!$B$17,J$4-1) -> 718008.77 | ... V13: =V12*(Control!$B$42+Control!$B$44)*POWER(1+Control!$B$17,V$4-1) -> 1289440.6
A14: Tours & activities income | C14: =IF(Control!$B$5>0,Control!$B$46*((Control!$B$20*(Control!$B$30*Control!$B$31+Control!$B$34*Control!$B$35+IF(AND(Control!$B$6="Y",C$4>=Control!$B$39),Control!$B$37*Control!$B$38,0)))/(Control!$B$20*(Control!$B$30*Control!$B$31+Control!$B$34*Control!$B$35+IF(AND(Control!$B$5>0,Control!$B$6="Y",1>=Control!$B$39),Control!$B$37*Control!$B$38,0))))*POWER(1+Control!$B$17,C$4-1),0) -> 2045556.5 | D14: =IF(Control!$B$5>0,Control!$B$46*((Control!$B$20*(Control!$B$30*Control!$B$31+Control!$B$34*Control!$B$35+IF(AND(Control!$B$6="Y",D$4>=Control!$B$39),Control!$B$37*Control!$B$38,0)))/(Control!$B$20*(Control!$B$30*Control!$B$31+Control!$B$34*Control!$B$35+IF(AND(Control!$B$5>0,Control!$B$6="Y",1>=Control!$B$39),Control!$B$37*Control!$B$38,0))))*POWER(1+Control!$B$17,D$4-1),0) -> 2147834.3 | E14: =IF(Control!$B$5>0,Control!$B$46*((Control!$B$20*(Control!$B$30*Control!$B$31+Control!$B$34*Control!$B$35+IF(AND(Control!$B$6="Y",E$4>=Control!$B$39),Control!$B$37*Control!$B$38,0)))/(Control!$B$20*(Control!$B$30*Control!$B$31+Control!$B$34*Control!$B$35+IF(AND(Control!$B$5>0,Control!$B$6="Y",1>=Control!$B$39),Control!$B$37*Control!$B$38,0))))*POWER(1+Control!$B$17,E$4-1),0) -> 2255226 | F14: =IF(Control!$B$5>0,Control!$B$46*((Control!$B$20*(Control!$B$30*Control!$B$31+Control!$B$34*Control!$B$35+IF(AND(Control!$B$6="Y",F$4>=Control!$B$39),Control!$B$37*Control!$B$38,0)))/(Control!$B$20*(Control!$B$30*Control!$B$31+Control!$B$34*Control!$B$35+IF(AND(Control!$B$5>0,Control!$B$6="Y",1>=Control!$B$39),Control!$B$37*Control!$B$38,0))))*POWER(1+Control!$B$17,F$4-1),0) -> 2367987.3 | G14: =IF(Control!$B$5>0,Control!$B$46*((Control!$B$20*(Control!$B$30*Control!$B$31+Control!$B$34*Control!$B$35+IF(AND(Control!$B$6="Y",G$4>=Control!$B$39),Control!$B$37*Control!$B$38,0)))/(Control!$B$20*(Control!$B$30*Control!$B$31+Control!$B$34*Control!$B$35+IF(AND(Control!$B$5>0,Control!$B$6="Y",1>=Control!$B$39),Control!$B$37*Control!$B$38,0))))*POWER(1+Control!$B$17,G$4-1),0) -> 2486386.7 | H14: =IF(Control!$B$5>0,Control!$B$46*((Control!$B$20*(Control!$B$30*Control!$B$31+Control!$B$34*Control!$B$35+IF(AND(Control!$B$6="Y",H$4>=Control!$B$39),Control!$B$37*Control!$B$38,0)))/(Control!$B$20*(Control!$B$30*Control!$B$31+Control!$B$34*Control!$B$35+IF(AND(Control!$B$5>0,Control!$B$6="Y",1>=Control!$B$39),Control!$B$37*Control!$B$38,0))))*POWER(1+Control!$B$17,H$4-1),0) -> 2610706 | I14: =IF(Control!$B$5>0,Control!$B$46*((Control!$B$20*(Control!$B$30*Control!$B$31+Control!$B$34*Control!$B$35+IF(AND(Control!$B$6="Y",I$4>=Control!$B$39),Control!$B$37*Control!$B$38,0)))/(Control!$B$20*(Control!$B$30*Control!$B$31+Control!$B$34*Control!$B$35+IF(AND(Control!$B$5>0,Control!$B$6="Y",1>=Control!$B$39),Control!$B$37*Control!$B$38,0))))*POWER(1+Control!$B$17,I$4-1),0) -> 2741241.3 | J14: =IF(Control!$B$5>0,Control!$B$46*((Control!$B$20*(Control!$B$30*Control!$B$31+Control!$B$34*Control!$B$35+IF(AND(Control!$B$6="Y",J$4>=Control!$B$39),Control!$B$37*Control!$B$38,0)))/(Control!$B$20*(Control!$B$30*Control!$B$31+Control!$B$34*Control!$B$35+IF(AND(Control!$B$5>0,Control!$B$6="Y",1>=Control!$B$39),Control!$B$37*Control!$B$38,0))))*POWER(1+Control!$B$17,J$4-1),0) -> 2878303.4 | ... V14: =IF(Control!$B$5>0,Control!$B$46*((Control!$B$20*(Control!$B$30*Control!$B$31+Control!$B$34*Control!$B$35+IF(AND(Control!$B$6="Y",V$4>=Control!$B$39),Control!$B$37*Control!$B$38,0)))/(Control!$B$20*(Control!$B$30*Control!$B$31+Control!$B$34*Control!$B$35+IF(AND(Control!$B$5>0,Control!$B$6="Y",1>=Control!$B$39),Control!$B$37*Control!$B$38,0))))*POWER(1+Control!$B$17,V$4-1),0) -> 5169019.4
A15: GROSS REVENUE | C15: =C10+C13+C14 -> 4821496.7 | D15: =D10+D13+D14 -> 5062571.5 | E15: =E10+E13+E14 -> 5315700.1 | F15: =F10+F13+F14 -> 5581485.1 | G15: =G10+G13+G14 -> 5860559.4 | H15: =H10+H13+H14 -> 6153587.3 | I15: =I10+I13+I14 -> 6461266.7 | J15: =J10+J13+J14 -> 6784330 | ... V15: =V10+V13+V14 -> 12183682
A16: OPERATING EXPENSES
A17: Channel commission | C17: =C10*Control!$B$52 -> 453132.96 | D17: =D10*Control!$B$52 -> 475789.6 | E17: =E10*Control!$B$52 -> 499579.08 | F17: =F10*Control!$B$52 -> 524558.04 | G17: =G10*Control!$B$52 -> 550785.94 | H17: =H10*Control!$B$52 -> 578325.24 | I17: =I10*Control!$B$52 -> 607241.5 | J17: =J10*Control!$B$52 -> 637603.57 | ... V17: =V10*Control!$B$52 -> 1145044.4
A18: Meals & provisions cost | C18: =IF(Control!$B$5>0,C12*(Control!$B$43+Control!$B$45)*POWER(1+Control!$B$18,C$4-1),0) -> 291585.96 | D18: =IF(Control!$B$5>0,D12*(Control!$B$43+Control!$B$45)*POWER(1+Control!$B$18,D$4-1),0) -> 306165.25 | E18: =IF(Control!$B$5>0,E12*(Control!$B$43+Control!$B$45)*POWER(1+Control!$B$18,E$4-1),0) -> 321473.52 | F18: =IF(Control!$B$5>0,F12*(Control!$B$43+Control!$B$45)*POWER(1+Control!$B$18,F$4-1),0) -> 337547.19 | G18: =IF(Control!$B$5>0,G12*(Control!$B$43+Control!$B$45)*POWER(1+Control!$B$18,G$4-1),0) -> 354424.55 | H18: =IF(Control!$B$5>0,H12*(Control!$B$43+Control!$B$45)*POWER(1+Control!$B$18,H$4-1),0) -> 372145.78 | I18: =IF(Control!$B$5>0,I12*(Control!$B$43+Control!$B$45)*POWER(1+Control!$B$18,I$4-1),0) -> 390753.07 | J18: =IF(Control!$B$5>0,J12*(Control!$B$43+Control!$B$45)*POWER(1+Control!$B$18,J$4-1),0) -> 410290.72 | ... V18: =IF(Control!$B$5>0,V12*(Control!$B$43+Control!$B$45)*POWER(1+Control!$B$18,V$4-1),0) -> 736823.19
A19: Tours & activities cost | C19: =IF(Control!$B$5>0,Control!$B$47*((Control!$B$20*(Control!$B$30*Control!$B$31+Control!$B$34*Control!$B$35+IF(AND(Control!$B$6="Y",C$4>=Control!$B$39),Control!$B$37*Control!$B$38,0)))/(Control!$B$20*(Control!$B$30*Control!$B$31+Control!$B$34*Control!$B$35+IF(AND(Control!$B$5>0,Control!$B$6="Y",1>=Control!$B$39),Control!$B$37*Control!$B$38,0))))*POWER(1+Control!$B$18,C$4-1),0) -> 1493746.3 | D19: =IF(Control!$B$5>0,Control!$B$47*((Control!$B$20*(Control!$B$30*Control!$B$31+Control!$B$34*Control!$B$35+IF(AND(Control!$B$6="Y",D$4>=Control!$B$39),Control!$B$37*Control!$B$38,0)))/(Control!$B$20*(Control!$B$30*Control!$B$31+Control!$B$34*Control!$B$35+IF(AND(Control!$B$5>0,Control!$B$6="Y",1>=Control!$B$39),Control!$B$37*Control!$B$38,0))))*POWER(1+Control!$B$18,D$4-1),0) -> 1568433.6 | E19: =IF(Control!$B$5>0,Control!$B$47*((Control!$B$20*(Control!$B$30*Control!$B$31+Control!$B$34*Control!$B$35+IF(AND(Control!$B$6="Y",E$4>=Control!$B$39),Control!$B$37*Control!$B$38,0)))/(Control!$B$20*(Control!$B$30*Control!$B$31+Control!$B$34*Control!$B$35+IF(AND(Control!$B$5>0,Control!$B$6="Y",1>=Control!$B$39),Control!$B$37*Control!$B$38,0))))*POWER(1+Control!$B$18,E$4-1),0) -> 1646855.3 | F19: =IF(Control!$B$5>0,Control!$B$47*((Control!$B$20*(Control!$B$30*Control!$B$31+Control!$B$34*Control!$B$35+IF(AND(Control!$B$6="Y",F$4>=Control!$B$39),Control!$B$37*Control!$B$38,0)))/(Control!$B$20*(Control!$B$30*Control!$B$31+Control!$B$34*Control!$B$35+IF(AND(Control!$B$5>0,Control!$B$6="Y",1>=Control!$B$39),Control!$B$37*Control!$B$38,0))))*POWER(1+Control!$B$18,F$4-1),0) -> 1729198 | G19: =IF(Control!$B$5>0,Control!$B$47*((Control!$B$20*(Control!$B$30*Control!$B$31+Control!$B$34*Control!$B$35+IF(AND(Control!$B$6="Y",G$4>=Control!$B$39),Control!$B$37*Control!$B$38,0)))/(Control!$B$20*(Control!$B$30*Control!$B$31+Control!$B$34*Control!$B$35+IF(AND(Control!$B$5>0,Control!$B$6="Y",1>=Control!$B$39),Control!$B$37*Control!$B$38,0))))*POWER(1+Control!$B$18,G$4-1),0) -> 1815657.9 | H19: =IF(Control!$B$5>0,Control!$B$47*((Control!$B$20*(Control!$B$30*Control!$B$31+Control!$B$34*Control!$B$35+IF(AND(Control!$B$6="Y",H$4>=Control!$B$39),Control!$B$37*Control!$B$38,0)))/(Control!$B$20*(Control!$B$30*Control!$B$31+Control!$B$34*Control!$B$35+IF(AND(Control!$B$5>0,Control!$B$6="Y",1>=Control!$B$39),Control!$B$37*Control!$B$38,0))))*POWER(1+Control!$B$18,H$4-1),0) -> 1906440.8 | I19: =IF(Control!$B$5>0,Control!$B$47*((Control!$B$20*(Control!$B$30*Control!$B$31+Control!$B$34*Control!$B$35+IF(AND(Control!$B$6="Y",I$4>=Control!$B$39),Control!$B$37*Control!$B$38,0)))/(Control!$B$20*(Control!$B$30*Control!$B$31+Control!$B$34*Control!$B$35+IF(AND(Control!$B$5>0,Control!$B$6="Y",1>=Control!$B$39),Control!$B$37*Control!$B$38,0))))*POWER(1+Control!$B$18,I$4-1),0) -> 2001762.8 | J19: =IF(Control!$B$5>0,Control!$B$47*((Control!$B$20*(Control!$B$30*Control!$B$31+Control!$B$34*Control!$B$35+IF(AND(Control!$B$6="Y",J$4>=Control!$B$39),Control!$B$37*Control!$B$38,0)))/(Control!$B$20*(Control!$B$30*Control!$B$31+Control!$B$34*Control!$B$35+IF(AND(Control!$B$5>0,Control!$B$6="Y",1>=Control!$B$39),Control!$B$37*Control!$B$38,0))))*POWER(1+Control!$B$18,J$4-1),0) -> 2101851 | ... V19: =IF(Control!$B$5>0,Control!$B$47*((Control!$B$20*(Control!$B$30*Control!$B$31+Control!$B$34*Control!$B$35+IF(AND(Control!$B$6="Y",V$4>=Control!$B$39),Control!$B$37*Control!$B$38,0)))/(Control!$B$20*(Control!$B$30*Control!$B$31+Control!$B$34*Control!$B$35+IF(AND(Control!$B$5>0,Control!$B$6="Y",1>=Control!$B$39),Control!$B$37*Control!$B$38,0))))*POWER(1+Control!$B$18,V$4-1),0) -> 3774622.4
A20: Salaries & wages | C20: =IF(Control!$B$5>0,Control!$B$48*12*POWER(1+Control!$B$18,C$4-1),0) -> 360000 | D20: =IF(Control!$B$5>0,Control!$B$48*12*POWER(1+Control!$B$18,D$4-1),0) -> 378000 | E20: =IF(Control!$B$5>0,Control!$B$48*12*POWER(1+Control!$B$18,E$4-1),0) -> 396900 | F20: =IF(Control!$B$5>0,Control!$B$48*12*POWER(1+Control!$B$18,F$4-1),0) -> 416745 | G20: =IF(Control!$B$5>0,Control!$B$48*12*POWER(1+Control!$B$18,G$4-1),0) -> 437582.25 | H20: =IF(Control!$B$5>0,Control!$B$48*12*POWER(1+Control!$B$18,H$4-1),0) -> 459461.36 | I20: =IF(Control!$B$5>0,Control!$B$48*12*POWER(1+Control!$B$18,I$4-1),0) -> 482434.43 | J20: =IF(Control!$B$5>0,Control!$B$48*12*POWER(1+Control!$B$18,J$4-1),0) -> 506556.15 | ... V20: =IF(Control!$B$5>0,Control!$B$48*12*POWER(1+Control!$B$18,V$4-1),0) -> 909702.07
A21: Utilities & municipal | C21: =IF(Control!$B$5>0,Control!$B$49*12*POWER(1+Control!$B$18,C$4-1),0) -> 81600 | D21: =IF(Control!$B$5>0,Control!$B$49*12*POWER(1+Control!$B$18,D$4-1),0) -> 85680 | E21: =IF(Control!$B$5>0,Control!$B$49*12*POWER(1+Control!$B$18,E$4-1),0) -> 89964 | F21: =IF(Control!$B$5>0,Control!$B$49*12*POWER(1+Control!$B$18,F$4-1),0) -> 94462.2 | G21: =IF(Control!$B$5>0,Control!$B$49*12*POWER(1+Control!$B$18,G$4-1),0) -> 99185.31 | H21: =IF(Control!$B$5>0,Control!$B$49*12*POWER(1+Control!$B$18,H$4-1),0) -> 104144.58 | I21: =IF(Control!$B$5>0,Control!$B$49*12*POWER(1+Control!$B$18,I$4-1),0) -> 109351.8 | J21: =IF(Control!$B$5>0,Control!$B$49*12*POWER(1+Control!$B$18,J$4-1),0) -> 114819.39 | ... V21: =IF(Control!$B$5>0,Control!$B$49*12*POWER(1+Control!$B$18,V$4-1),0) -> 206199.14
A22: Repairs & maintenance | C22: =IF(Control!$B$5>0,Control!$B$50*12*POWER(1+Control!$B$18,C$4-1),0) -> 42000 | D22: =IF(Control!$B$5>0,Control!$B$50*12*POWER(1+Control!$B$18,D$4-1),0) -> 44100 | E22: =IF(Control!$B$5>0,Control!$B$50*12*POWER(1+Control!$B$18,E$4-1),0) -> 46305 | F22: =IF(Control!$B$5>0,Control!$B$50*12*POWER(1+Control!$B$18,F$4-1),0) -> 48620.25 | G22: =IF(Control!$B$5>0,Control!$B$50*12*POWER(1+Control!$B$18,G$4-1),0) -> 51051.262 | H22: =IF(Control!$B$5>0,Control!$B$50*12*POWER(1+Control!$B$18,H$4-1),0) -> 53603.826 | I22: =IF(Control!$B$5>0,Control!$B$50*12*POWER(1+Control!$B$18,I$4-1),0) -> 56284.017 | J22: =IF(Control!$B$5>0,Control!$B$50*12*POWER(1+Control!$B$18,J$4-1),0) -> 59098.218 | ... V22: =IF(Control!$B$5>0,Control!$B$50*12*POWER(1+Control!$B$18,V$4-1),0) -> 106131.91
A23: Other operating | C23: =IF(Control!$B$5>0,Control!$B$51*12*POWER(1+Control!$B$18,C$4-1),0) -> 60000 | D23: =IF(Control!$B$5>0,Control!$B$51*12*POWER(1+Control!$B$18,D$4-1),0) -> 63000 | E23: =IF(Control!$B$5>0,Control!$B$51*12*POWER(1+Control!$B$18,E$4-1),0) -> 66150 | F23: =IF(Control!$B$5>0,Control!$B$51*12*POWER(1+Control!$B$18,F$4-1),0) -> 69457.5 | G23: =IF(Control!$B$5>0,Control!$B$51*12*POWER(1+Control!$B$18,G$4-1),0) -> 72930.375 | H23: =IF(Control!$B$5>0,Control!$B$51*12*POWER(1+Control!$B$18,H$4-1),0) -> 76576.894 | I23: =IF(Control!$B$5>0,Control!$B$51*12*POWER(1+Control!$B$18,I$4-1),0) -> 80405.738 | J23: =IF(Control!$B$5>0,Control!$B$51*12*POWER(1+Control!$B$18,J$4-1),0) -> 84426.025 | ... V23: =IF(Control!$B$5>0,Control!$B$51*12*POWER(1+Control!$B$18,V$4-1),0) -> 151617.01
A24: FF&E / capex reserve | C24: =C10*Control!$B$26 -> 90626.591 | D24: =D10*Control!$B$26 -> 95157.921 | E24: =E10*Control!$B$26 -> 99915.817 | F24: =F10*Control!$B$26 -> 104911.61 | G24: =G10*Control!$B$26 -> 110157.19 | H24: =H10*Control!$B$26 -> 115665.05 | I24: =I10*Control!$B$26 -> 121448.3 | J24: =J10*Control!$B$26 -> 127520.71 | ... V24: =V10*Control!$B$26 -> 229008.88
A25: TOTAL EXPENSES | C25: =SUM(C17:C24) -> 2872691.8 | D25: =SUM(D17:D24) -> 3016326.4 | E25: =SUM(E17:E24) -> 3167142.7 | F25: =SUM(F17:F24) -> 3325499.8 | G25: =SUM(G17:G24) -> 3491774.8 | H25: =SUM(H17:H24) -> 3666363.5 | I25: =SUM(I17:I24) -> 3849681.7 | J25: =SUM(J17:J24) -> 4042165.8 | ... V25: =SUM(V17:V24) -> 7259149
A26: NET OPERATING INCOME (NOI, pre-tax) | C26: =C15-C25 -> 1948804.9 | D26: =D15-D25 -> 2046245.2 | E26: =E15-E25 -> 2148557.4 | F26: =F15-F25 -> 2255985.3 | G26: =G15-G25 -> 2368784.6 | H26: =H15-H25 -> 2487223.8 | I26: =I15-I25 -> 2611585 | J26: =J15-J25 -> 2742164.2 | ... V26: =V15-V25 -> 4924533
A27: Income tax | C27: =-C26*Control!$B$23 -> -526177.33 | D27: =-D26*Control!$B$23 -> -552486.2 | E27: =-E26*Control!$B$23 -> -580110.51 | F27: =-F26*Control!$B$23 -> -609116.03 | G27: =-G26*Control!$B$23 -> -639571.83 | H27: =-H26*Control!$B$23 -> -671550.42 | I27: =-I26*Control!$B$23 -> -705127.95 | J27: =-J26*Control!$B$23 -> -740384.34 | ... V27: =-V26*Control!$B$23 -> -1329623.9
A28: NET PROFIT AFTER TAX | C28: =C26+C27 -> 1422627.6 | D28: =D26+D27 -> 1493759 | E28: =E26+E27 -> 1568446.9 | F28: =F26+F27 -> 1646869.3 | G28: =G26+G27 -> 1729212.7 | H28: =H26+H27 -> 1815673.4 | I28: =I26+I27 -> 1906457 | J28: =J26+J27 -> 2001779.9 | ... V28: =V26+V27 -> 3594909.1

Sheet Beachside P&L
A1: BEACHSIDE ESCAPE — P&L (annual, 20-year)
A2: Big Bay. 10 months long-term + Dec/Jan peak nightly (90% occupancy). After reserve, after tax.
A4: Year | C4: 1 | D4: 2 | E4: 3 | F4: 4 | G4: 5 | H4: 6 | I4: 7 | J4: 8 | K4: 9 | L4: 10 | M4: 11 | N4: 12 | O4: 13 | P4: 14 | Q4: 15 | R4: 16 | S4: 17 | T4: 18 | U4: 19 | V4: 20
A6: Long-term rental income | C6: =IF(Control!$B$7>0,Control!$B$54*Control!$B$55*POWER(1+Control!$B$17,C$4-1),0) -> 300000 | D6: =IF(Control!$B$7>0,Control!$B$54*Control!$B$55*POWER(1+Control!$B$17,D$4-1),0) -> 315000 | E6: =IF(Control!$B$7>0,Control!$B$54*Control!$B$55*POWER(1+Control!$B$17,E$4-1),0) -> 330750 | F6: =IF(Control!$B$7>0,Control!$B$54*Control!$B$55*POWER(1+Control!$B$17,F$4-1),0) -> 347287.5 | G6: =IF(Control!$B$7>0,Control!$B$54*Control!$B$55*POWER(1+Control!$B$17,G$4-1),0) -> 364651.88 | H6: =IF(Control!$B$7>0,Control!$B$54*Control!$B$55*POWER(1+Control!$B$17,H$4-1),0) -> 382884.47 | I6: =IF(Control!$B$7>0,Control!$B$54*Control!$B$55*POWER(1+Control!$B$17,I$4-1),0) -> 402028.69 | J6: =IF(Control!$B$7>0,Control!$B$54*Control!$B$55*POWER(1+Control!$B$17,J$4-1),0) -> 422130.13 | ... V6: =IF(Control!$B$7>0,Control!$B$54*Control!$B$55*POWER(1+Control!$B$17,V$4-1),0) -> 758085.06
A7: Peak nightly income (Dec+Jan) | C7: =IF(Control!$B$7>0,Control!$B$57*Control!$B$58*Control!$B$59*Control!$B$60*POWER(1+Control!$B$17,C$4-1),0) -> 243000 | D7: =IF(Control!$B$7>0,Control!$B$57*Control!$B$58*Control!$B$59*Control!$B$60*POWER(1+Control!$B$17,D$4-1),0) -> 255150 | E7: =IF(Control!$B$7>0,Control!$B$57*Control!$B$58*Control!$B$59*Control!$B$60*POWER(1+Control!$B$17,E$4-1),0) -> 267907.5 | F7: =IF(Control!$B$7>0,Control!$B$57*Control!$B$58*Control!$B$59*Control!$B$60*POWER(1+Control!$B$17,F$4-1),0) -> 281302.88 | G7: =IF(Control!$B$7>0,Control!$B$57*Control!$B$58*Control!$B$59*Control!$B$60*POWER(1+Control!$B$17,G$4-1),0) -> 295368.02 | H7: =IF(Control!$B$7>0,Control!$B$57*Control!$B$58*Control!$B$59*Control!$B$60*POWER(1+Control!$B$17,H$4-1),0) -> 310136.42 | I7: =IF(Control!$B$7>0,Control!$B$57*Control!$B$58*Control!$B$59*Control!$B$60*POWER(1+Control!$B$17,I$4-1),0) -> 325643.24 | J7: =IF(Control!$B$7>0,Control!$B$57*Control!$B$58*Control!$B$59*Control!$B$60*POWER(1+Control!$B$17,J$4-1),0) -> 341925.4 | ... V7: =IF(Control!$B$7>0,Control!$B$57*Control!$B$58*Control!$B$59*Control!$B$60*POWER(1+Control!$B$17,V$4-1),0) -> 614048.9
A8: GROSS REVENUE | C8: =SUM(C6:C7) -> 543000 | D8: =SUM(D6:D7) -> 570150 | E8: =SUM(E6:E7) -> 598657.5 | F8: =SUM(F6:F7) -> 628590.38 | G8: =SUM(G6:G7) -> 660019.89 | H8: =SUM(H6:H7) -> 693020.89 | I8: =SUM(I6:I7) -> 727671.93 | J8: =SUM(J6:J7) -> 764055.53 | ... V8: =SUM(V6:V7) -> 1372134
A9: OPERATING EXPENSES
A10: Channel commission (nightly only) | C10: =C7*Control!$B$63 -> 48600 | D10: =D7*Control!$B$63 -> 51030 | E10: =E7*Control!$B$63 -> 53581.5 | F10: =F7*Control!$B$63 -> 56260.575 | G10: =G7*Control!$B$63 -> 59073.604 | H10: =H7*Control!$B$63 -> 62027.284 | I10: =I7*Control!$B$63 -> 65128.648 | J10: =J7*Control!$B$63 -> 68385.081 | ... V10: =V7*Control!$B$63 -> 122809.78
A11: Utilities & municipal | C11: =IF(Control!$B$7>0,Control!$B$64*12*POWER(1+Control!$B$18,C$4-1),0) -> 12000 | D11: =IF(Control!$B$7>0,Control!$B$64*12*POWER(1+Control!$B$18,D$4-1),0) -> 12600 | E11: =IF(Control!$B$7>0,Control!$B$64*12*POWER(1+Control!$B$18,E$4-1),0) -> 13230 | F11: =IF(Control!$B$7>0,Control!$B$64*12*POWER(1+Control!$B$18,F$4-1),0) -> 13891.5 | G11: =IF(Control!$B$7>0,Control!$B$64*12*POWER(1+Control!$B$18,G$4-1),0) -> 14586.075 | H11: =IF(Control!$B$7>0,Control!$B$64*12*POWER(1+Control!$B$18,H$4-1),0) -> 15315.379 | I11: =IF(Control!$B$7>0,Control!$B$64*12*POWER(1+Control!$B$18,I$4-1),0) -> 16081.148 | J11: =IF(Control!$B$7>0,Control!$B$64*12*POWER(1+Control!$B$18,J$4-1),0) -> 16885.205 | ... V11: =IF(Control!$B$7>0,Control!$B$64*12*POWER(1+Control!$B$18,V$4-1),0) -> 30323.402
A12: Repairs & maintenance | C12: =IF(Control!$B$7>0,Control!$B$65*12*POWER(1+Control!$B$18,C$4-1),0) -> 12000 | D12: =IF(Control!$B$7>0,Control!$B$65*12*POWER(1+Control!$B$18,D$4-1),0) -> 12600 | E12: =IF(Control!$B$7>0,Control!$B$65*12*POWER(1+Control!$B$18,E$4-1),0) -> 13230 | F12: =IF(Control!$B$7>0,Control!$B$65*12*POWER(1+Control!$B$18,F$4-1),0) -> 13891.5 | G12: =IF(Control!$B$7>0,Control!$B$65*12*POWER(1+Control!$B$18,G$4-1),0) -> 14586.075 | H12: =IF(Control!$B$7>0,Control!$B$65*12*POWER(1+Control!$B$18,H$4-1),0) -> 15315.379 | I12: =IF(Control!$B$7>0,Control!$B$65*12*POWER(1+Control!$B$18,I$4-1),0) -> 16081.148 | J12: =IF(Control!$B$7>0,Control!$B$65*12*POWER(1+Control!$B$18,J$4-1),0) -> 16885.205 | ... V12: =IF(Control!$B$7>0,Control!$B$65*12*POWER(1+Control!$B$18,V$4-1),0) -> 30323.402
A13: Levies | C13: =IF(Control!$B$7>0,Control!$B$66*12*POWER(1+Control!$B$18,C$4-1),0) -> 45600 | D13: =IF(Control!$B$7>0,Control!$B$66*12*POWER(1+Control!$B$18,D$4-1),0) -> 47880 | E13: =IF(Control!$B$7>0,Control!$B$66*12*POWER(1+Control!$B$18,E$4-1),0) -> 50274 | F13: =IF(Control!$B$7>0,Control!$B$66*12*POWER(1+Control!$B$18,F$4-1),0) -> 52787.7 | G13: =IF(Control!$B$7>0,Control!$B$66*12*POWER(1+Control!$B$18,G$4-1),0) -> 55427.085 | H13: =IF(Control!$B$7>0,Control!$B$66*12*POWER(1+Control!$B$18,H$4-1),0) -> 58198.439 | I13: =IF(Control!$B$7>0,Control!$B$66*12*POWER(1+Control!$B$18,I$4-1),0) -> 61108.361 | J13: =IF(Control!$B$7>0,Control!$B$66*12*POWER(1+Control!$B$18,J$4-1),0) -> 64163.779 | ... V13: =IF(Control!$B$7>0,Control!$B$66*12*POWER(1+Control!$B$18,V$4-1),0) -> 115228.93
A14: FF&E / capex reserve | C14: =C8*Control!$B$26 -> 21720 | D14: =D8*Control!$B$26 -> 22806 | E14: =E8*Control!$B$26 -> 23946.3 | F14: =F8*Control!$B$26 -> 25143.615 | G14: =G8*Control!$B$26 -> 26400.796 | H14: =H8*Control!$B$26 -> 27720.836 | I14: =I8*Control!$B$26 -> 29106.877 | J14: =J8*Control!$B$26 -> 30562.221 | ... V14: =V8*Control!$B$26 -> 54885.358
A15: TOTAL EXPENSES | C15: =SUM(C10:C14) -> 139920 | D15: =SUM(D10:D14) -> 146916 | E15: =SUM(E10:E14) -> 154261.8 | F15: =SUM(F10:F14) -> 161974.89 | G15: =SUM(G10:G14) -> 170073.63 | H15: =SUM(H10:H14) -> 178577.32 | I15: =SUM(I10:I14) -> 187506.18 | J15: =SUM(J10:J14) -> 196881.49 | ... V15: =SUM(V10:V14) -> 353570.87
A16: NET OPERATING INCOME (NOI, pre-tax) | C16: =C8-C15 -> 403080 | D16: =D8-D15 -> 423234 | E16: =E8-E15 -> 444395.7 | F16: =F8-F15 -> 466615.49 | G16: =G8-G15 -> 489946.26 | H16: =H8-H15 -> 514443.57 | I16: =I8-I15 -> 540165.75 | J16: =J8-J15 -> 567174.04 | ... V16: =V8-V15 -> 1018563.1
A17: Income tax | C17: =-C16*Control!$B$23 -> -108831.6 | D17: =-D16*Control!$B$23 -> -114273.18 | E17: =-E16*Control!$B$23 -> -119986.84 | F17: =-F16*Control!$B$23 -> -125986.18 | G17: =-G16*Control!$B$23 -> -132285.49 | H17: =-H16*Control!$B$23 -> -138899.76 | I17: =-I16*Control!$B$23 -> -145844.75 | J17: =-J16*Control!$B$23 -> -153136.99 | ... V17: =-V16*Control!$B$23 -> -275012.03
A18: NET PROFIT AFTER TAX | C18: =C16+C17 -> 294248.4 | D18: =D16+D17 -> 308960.82 | E18: =E16+E17 -> 324408.86 | F18: =F16+F17 -> 340629.3 | G18: =G16+G17 -> 357660.77 | H18: =H16+H17 -> 375543.81 | I18: =I16+I17 -> 394321 | J18: =J16+J17 -> 414037.05 | ... V18: =V16+V17 -> 743551.05

Sheet Menlyn P&L
A1: MENLYN MAIN — P&L (annual, 20-year)
A2: Long-term residential rental only. After reserve, after tax.
A4: Year | C4: 1 | D4: 2 | E4: 3 | F4: 4 | G4: 5 | H4: 6 | I4: 7 | J4: 8 | K4: 9 | L4: 10 | M4: 11 | N4: 12 | O4: 13 | P4: 14 | Q4: 15 | R4: 16 | S4: 17 | T4: 18 | U4: 19 | V4: 20
A6: GROSS REVENUE (rental) | C6: =IF(Control!$B$8>0,Control!$B$68*12*POWER(1+Control!$B$17,C$4-1),0) -> 336000 | D6: =IF(Control!$B$8>0,Control!$B$68*12*POWER(1+Control!$B$17,D$4-1),0) -> 352800 | E6: =IF(Control!$B$8>0,Control!$B$68*12*POWER(1+Control!$B$17,E$4-1),0) -> 370440 | F6: =IF(Control!$B$8>0,Control!$B$68*12*POWER(1+Control!$B$17,F$4-1),0) -> 388962 | G6: =IF(Control!$B$8>0,Control!$B$68*12*POWER(1+Control!$B$17,G$4-1),0) -> 408410.1 | H6: =IF(Control!$B$8>0,Control!$B$68*12*POWER(1+Control!$B$17,H$4-1),0) -> 428830.61 | I6: =IF(Control!$B$8>0,Control!$B$68*12*POWER(1+Control!$B$17,I$4-1),0) -> 450272.14 | J6: =IF(Control!$B$8>0,Control!$B$68*12*POWER(1+Control!$B$17,J$4-1),0) -> 472785.74 | ... V6: =IF(Control!$B$8>0,Control!$B$68*12*POWER(1+Control!$B$17,V$4-1),0) -> 849055.27
A7: OPERATING EXPENSES
A8: Utilities & municipal | C8: =IF(Control!$B$8>0,Control!$B$70*12*POWER(1+Control!$B$18,C$4-1),0) -> 10800 | D8: =IF(Control!$B$8>0,Control!$B$70*12*POWER(1+Control!$B$18,D$4-1),0) -> 11340 | E8: =IF(Control!$B$8>0,Control!$B$70*12*POWER(1+Control!$B$18,E$4-1),0) -> 11907 | F8: =IF(Control!$B$8>0,Control!$B$70*12*POWER(1+Control!$B$18,F$4-1),0) -> 12502.35 | G8: =IF(Control!$B$8>0,Control!$B$70*12*POWER(1+Control!$B$18,G$4-1),0) -> 13127.468 | H8: =IF(Control!$B$8>0,Control!$B$70*12*POWER(1+Control!$B$18,H$4-1),0) -> 13783.841 | I8: =IF(Control!$B$8>0,Control!$B$70*12*POWER(1+Control!$B$18,I$4-1),0) -> 14473.033 | J8: =IF(Control!$B$8>0,Control!$B$70*12*POWER(1+Control!$B$18,J$4-1),0) -> 15196.685 | ... V8: =IF(Control!$B$8>0,Control!$B$70*12*POWER(1+Control!$B$18,V$4-1),0) -> 27291.062
A9: Repairs & maintenance | C9: =IF(Control!$B$8>0,Control!$B$71*12*POWER(1+Control!$B$18,C$4-1),0) -> 12000 | D9: =IF(Control!$B$8>0,Control!$B$71*12*POWER(1+Control!$B$18,D$4-1),0) -> 12600 | E9: =IF(Control!$B$8>0,Control!$B$71*12*POWER(1+Control!$B$18,E$4-1),0) -> 13230 | F9: =IF(Control!$B$8>0,Control!$B$71*12*POWER(1+Control!$B$18,F$4-1),0) -> 13891.5 | G9: =IF(Control!$B$8>0,Control!$B$71*12*POWER(1+Control!$B$18,G$4-1),0) -> 14586.075 | H9: =IF(Control!$B$8>0,Control!$B$71*12*POWER(1+Control!$B$18,H$4-1),0) -> 15315.379 | I9: =IF(Control!$B$8>0,Control!$B$71*12*POWER(1+Control!$B$18,I$4-1),0) -> 16081.148 | J9: =IF(Control!$B$8>0,Control!$B$71*12*POWER(1+Control!$B$18,J$4-1),0) -> 16885.205 | ... V9: =IF(Control!$B$8>0,Control!$B$71*12*POWER(1+Control!$B$18,V$4-1),0) -> 30323.402
A10: Levies / rates | C10: =IF(Control!$B$8>0,Control!$B$72*12*POWER(1+Control!$B$18,C$4-1),0) -> 42000 | D10: =IF(Control!$B$8>0,Control!$B$72*12*POWER(1+Control!$B$18,D$4-1),0) -> 44100 | E10: =IF(Control!$B$8>0,Control!$B$72*12*POWER(1+Control!$B$18,E$4-1),0) -> 46305 | F10: =IF(Control!$B$8>0,Control!$B$72*12*POWER(1+Control!$B$18,F$4-1),0) -> 48620.25 | G10: =IF(Control!$B$8>0,Control!$B$72*12*POWER(1+Control!$B$18,G$4-1),0) -> 51051.262 | H10: =IF(Control!$B$8>0,Control!$B$72*12*POWER(1+Control!$B$18,H$4-1),0) -> 53603.826 | I10: =IF(Control!$B$8>0,Control!$B$72*12*POWER(1+Control!$B$18,I$4-1),0) -> 56284.017 | J10: =IF(Control!$B$8>0,Control!$B$72*12*POWER(1+Control!$B$18,J$4-1),0) -> 59098.218 | ... V10: =IF(Control!$B$8>0,Control!$B$72*12*POWER(1+Control!$B$18,V$4-1),0) -> 106131.91
A11: FF&E / capex reserve | C11: =C6*Control!$B$26 -> 13440 | D11: =D6*Control!$B$26 -> 14112 | E11: =E6*Control!$B$26 -> 14817.6 | F11: =F6*Control!$B$26 -> 15558.48 | G11: =G6*Control!$B$26 -> 16336.404 | H11: =H6*Control!$B$26 -> 17153.224 | I11: =I6*Control!$B$26 -> 18010.885 | J11: =J6*Control!$B$26 -> 18911.43 | ... V11: =V6*Control!$B$26 -> 33962.211
A12: TOTAL EXPENSES | C12: =SUM(C8:C11) -> 78240 | D12: =SUM(D8:D11) -> 82152 | E12: =SUM(E8:E11) -> 86259.6 | F12: =SUM(F8:F11) -> 90572.58 | G12: =SUM(G8:G11) -> 95101.209 | H12: =SUM(H8:H11) -> 99856.269 | I12: =SUM(I8:I11) -> 104849.08 | J12: =SUM(J8:J11) -> 110091.54 | ... V12: =SUM(V8:V11) -> 197708.58
A13: NET OPERATING INCOME (NOI, pre-tax) | C13: =C6-C12 -> 257760 | D13: =D6-D12 -> 270648 | E13: =E6-E12 -> 284180.4 | F13: =F6-F12 -> 298389.42 | G13: =G6-G12 -> 313308.89 | H13: =H6-H12 -> 328974.34 | I13: =I6-I12 -> 345423.05 | J13: =J6-J12 -> 362694.2 | ... V13: =V6-V12 -> 651346.68
A14: Income tax | C14: =-C13*Control!$B$23 -> -69595.2 | D14: =-D13*Control!$B$23 -> -73074.96 | E14: =-E13*Control!$B$23 -> -76728.708 | F14: =-F13*Control!$B$23 -> -80565.143 | G14: =-G13*Control!$B$23 -> -84593.401 | H14: =-H13*Control!$B$23 -> -88823.071 | I14: =-I13*Control!$B$23 -> -93264.224 | J14: =-J13*Control!$B$23 -> -97927.435 | ... V14: =-V13*Control!$B$23 -> -175863.6
A15: NET PROFIT AFTER TAX | C15: =C13+C14 -> 188164.8 | D15: =D13+D14 -> 197573.04 | E15: =E13+E14 -> 207451.69 | F15: =F13+F14 -> 217824.28 | G15: =G13+G14 -> 228715.49 | H15: =H13+H14 -> 240151.26 | I15: =I13+I14 -> 252158.83 | J15: =J13+J14 -> 264766.77 | ... V15: =V13+V14 -> 475483.08

Sheet Valuation
A1: PROPERTY VALUATION — independent (income & comparable, NOT back-solved from buy-in)
A2: Two industry methods per asset. Partner share % inputs on Control include/exclude each property from investor economics; 0% excludes, >0% includes. Winchester is a development expansion option and only activates if African Sky share > 0%.
A4: Valuation basis | C4: African Sky | D4: Beachside | E4: Menlyn | F4: Portfolio
A5: In-place annual NOI (active properties only; AS reflects Winchester only if expansion is active) | C5: ='African Sky P&L'!D26 -> 2046245.2 | D5: ='Beachside P&L'!C16 -> 403080 | E5: ='Menlyn P&L'!C13 -> 257760 | F5: =SUM(C5:E5) -> 2707085.2
A6: Market cap rate (income approach) | C6: =Control!$B$74 -> 0.1 | D6: =Control!$B$75 -> 0.075 | E6: =Control!B76 -> 0.085
A7: Income-capitalised value (NOI ÷ cap rate) | C7: =IFERROR(C5/C6,0) -> 20462452 | D7: =IFERROR(D5/D6,0) -> 5374400 | E7: =IFERROR(E5/E6,0) -> 3032470.6
A8: Independent comparable value (CMA input — editable; income approach corroborates below) | C8: =IF(Control!$B$5>0,Control!$B$77+IF(AND(Control!$B$6="Y",Control!$B$5>0),Control!$B$40,0),0) -> 6000000 | D8: =IF(Control!$B$7>0,4000000,0) -> 4000000 | E8: =IF(Control!$B$8>0,2900000,0) -> 2900000 | F8: =SUM(C8:E8) -> 12900000
A9: ADOPTED property value (conservative) | C9: =C8 -> 6000000 | D9: =D8 -> 4000000 | E9: =E8 -> 2900000 | F9: =SUM(C9:E9) -> 12900000
A10: Partner NAV @ property-specific % | C10: =C9*Control!$B$5 -> 3000000 | D10: =D9*Control!$B$7 -> 2000000 | E10: =E9*Control!$B$8 -> 1450000 | F10: =SUM(C10:E10) -> 6450000
A11: Income approach vs adopted (×, >1 = conservative) | C11: =IFERROR(C7/C9,0) -> 3.4104086 | D11: =IFERROR(D7/D9,0) -> 1.3436 | E11: =IFERROR(E7/E9,0) -> 1.0456795
A12: NOI yield on adopted value | C12: =IFERROR(C5/C9,0) -> 0.34104086 | D12: =IFERROR(D5/D9,0) -> 0.10077 | E12: =IFERROR(E5/E9,0) -> 0.088882759
A13: Memo: African Sky operating-business value (meals+tours net × 3, indicative) | C13: =IF(Control!$B$5>0,(('African Sky P&L'!D13-'African Sky P&L'!D18)+('African Sky P&L'!D14-'African Sky P&L'!D19))*3,0) -> 2427074
A15: v7.8 note: Beachside & Menlyn adopted values are now independent CMA inputs (D8/E8), no longer buy-in×2. Income-capitalised values (row 7) corroborate higher. Internal estimates pending a registered (SACPVP) valuation.

Sheet Portfolio NewCo
A1: PORTFOLIO — NewCo consolidated (20-year)
A2: NewCo owns 100% of the three properties. Partner owns 50% of NewCo. Distributions = 50% of after-tax profit, less any capex funded from NewCo cash.
A4: Year | B4: 1 | C4: 2 | D4: 3 | E4: 4 | F4: 5 | G4: 6 | H4: 7 | I4: 8 | J4: 9 | K4: 10 | L4: 11 | M4: 12 | N4: 13 | O4: 14 | P4: 15 | Q4: 16 | R4: 17 | S4: 18 | T4: 19 | U4: 20
A6: African Sky NOI | B6: ='African Sky P&L'!C26 -> 1948804.9 | C6: ='African Sky P&L'!D26 -> 2046245.2 | D6: ='African Sky P&L'!E26 -> 2148557.4 | E6: ='African Sky P&L'!F26 -> 2255985.3 | F6: ='African Sky P&L'!G26 -> 2368784.6 | G6: ='African Sky P&L'!H26 -> 2487223.8 | H6: ='African Sky P&L'!I26 -> 2611585 | I6: ='African Sky P&L'!J26 -> 2742164.2 | ... U6: ='African Sky P&L'!V26 -> 4924533
A7: Beachside NOI | B7: ='Beachside P&L'!C16 -> 403080 | C7: ='Beachside P&L'!D16 -> 423234 | D7: ='Beachside P&L'!E16 -> 444395.7 | E7: ='Beachside P&L'!F16 -> 466615.49 | F7: ='Beachside P&L'!G16 -> 489946.26 | G7: ='Beachside P&L'!H16 -> 514443.57 | H7: ='Beachside P&L'!I16 -> 540165.75 | I7: ='Beachside P&L'!J16 -> 567174.04 | ... U7: ='Beachside P&L'!V16 -> 1018563.1
A8: Menlyn NOI | B8: ='Menlyn P&L'!C13 -> 257760 | C8: ='Menlyn P&L'!D13 -> 270648 | D8: ='Menlyn P&L'!E13 -> 284180.4 | E8: ='Menlyn P&L'!F13 -> 298389.42 | F8: ='Menlyn P&L'!G13 -> 313308.89 | G8: ='Menlyn P&L'!H13 -> 328974.34 | H8: ='Menlyn P&L'!I13 -> 345423.05 | I8: ='Menlyn P&L'!J13 -> 362694.2 | ... U8: ='Menlyn P&L'!V13 -> 651346.68
A9: PORTFOLIO NOI | B9: =SUM(B6:B8) -> 2609644.9 | C9: =SUM(C6:C8) -> 2740127.2 | D9: =SUM(D6:D8) -> 2877133.5 | E9: =SUM(E6:E8) -> 3020990.2 | F9: =SUM(F6:F8) -> 3172039.7 | G9: =SUM(G6:G8) -> 3330641.7 | H9: =SUM(H6:H8) -> 3497173.8 | I9: =SUM(I6:I8) -> 3672032.5 | ... U9: =SUM(U6:U8) -> 6594442.8
A10: African Sky NPAT | B10: ='African Sky P&L'!C28 -> 1422627.6 | C10: ='African Sky P&L'!D28 -> 1493759 | D10: ='African Sky P&L'!E28 -> 1568446.9 | E10: ='African Sky P&L'!F28 -> 1646869.3 | F10: ='African Sky P&L'!G28 -> 1729212.7 | G10: ='African Sky P&L'!H28 -> 1815673.4 | H10: ='African Sky P&L'!I28 -> 1906457 | I10: ='African Sky P&L'!J28 -> 2001779.9 | ... U10: ='African Sky P&L'!V28 -> 3594909.1
A11: Beachside NPAT | B11: ='Beachside P&L'!C18 -> 294248.4 | C11: ='Beachside P&L'!D18 -> 308960.82 | D11: ='Beachside P&L'!E18 -> 324408.86 | E11: ='Beachside P&L'!F18 -> 340629.3 | F11: ='Beachside P&L'!G18 -> 357660.77 | G11: ='Beachside P&L'!H18 -> 375543.81 | H11: ='Beachside P&L'!I18 -> 394321 | I11: ='Beachside P&L'!J18 -> 414037.05 | ... U11: ='Beachside P&L'!V18 -> 743551.05
A12: Menlyn NPAT | B12: ='Menlyn P&L'!C15 -> 188164.8 | C12: ='Menlyn P&L'!D15 -> 197573.04 | D12: ='Menlyn P&L'!E15 -> 207451.69 | E12: ='Menlyn P&L'!F15 -> 217824.28 | F12: ='Menlyn P&L'!G15 -> 228715.49 | G12: ='Menlyn P&L'!H15 -> 240151.26 | H12: ='Menlyn P&L'!I15 -> 252158.83 | I12: ='Menlyn P&L'!J15 -> 264766.77 | ... U12: ='Menlyn P&L'!V15 -> 475483.08
A13: PORTFOLIO NPAT | B13: =SUM(B10:B12) -> 1905040.8 | C13: =SUM(C10:C12) -> 2000292.8 | D13: =SUM(D10:D12) -> 2100307.5 | E13: =SUM(E10:E12) -> 2205322.9 | F13: =SUM(F10:F12) -> 2315589 | G13: =SUM(G10:G12) -> 2431368.4 | H13: =SUM(H10:H12) -> 2552936.9 | I13: =SUM(I10:I12) -> 2680583.7 | ... U13: =SUM(U10:U12) -> 4813943.2
A14: Less: Winchester construction capex | B14: =-IF(AND(Control!$B$5>0,Control!$B$6="Y",B$4=Control!$B$39-1),Control!$B$40,0) -> 0 | C14: =-IF(AND(Control!$B$5>0,Control!$B$6="Y",C$4=Control!$B$39-1),Control!$B$40,0) -> 0 | D14: =-IF(AND(Control!$B$5>0,Control!$B$6="Y",D$4=Control!$B$39-1),Control!$B$40,0) -> 0 | E14: =-IF(AND(Control!$B$5>0,Control!$B$6="Y",E$4=Control!$B$39-1),Control!$B$40,0) -> 0 | F14: =-IF(AND(Control!$B$5>0,Control!$B$6="Y",F$4=Control!$B$39-1),Control!$B$40,0) -> 0 | G14: =-IF(AND(Control!$B$5>0,Control!$B$6="Y",G$4=Control!$B$39-1),Control!$B$40,0) -> 0 | H14: =-IF(AND(Control!$B$5>0,Control!$B$6="Y",H$4=Control!$B$39-1),Control!$B$40,0) -> 0 | I14: =-IF(AND(Control!$B$5>0,Control!$B$6="Y",I$4=Control!$B$39-1),Control!$B$40,0) -> 0 | ... U14: =-IF(AND(Control!$B$5>0,Control!$B$6="Y",U$4=Control!$B$39-1),Control!$B$40,0) -> 0
A15: Distributable profit | B15: =B13+B14 -> 1905040.8 | C15: =C13+C14 -> 2000292.8 | D15: =D13+D14 -> 2100307.5 | E15: =E13+E14 -> 2205322.9 | F15: =F13+F14 -> 2315589 | G15: =G13+G14 -> 2431368.4 | H15: =H13+H14 -> 2552936.9 | I15: =I13+I14 -> 2680583.7 | ... U15: =U13+U14 -> 4813943.2
A16: Partner distribution (property-specific %) | B16: =SUM(B24:B26) -> 952520.4 | C16: =SUM(C24:C26) -> 1000146.4 | D16: =SUM(D24:D26) -> 1050153.7 | E16: =SUM(E24:E26) -> 1102661.4 | F16: =SUM(F24:F26) -> 1157794.5 | G16: =SUM(G24:G26) -> 1215684.2 | H16: =SUM(H24:H26) -> 1276468.4 | I16: =SUM(I24:I26) -> 1340291.9 | ... U16: =SUM(U24:U26) -> 2406971.6
A17: Cumulative partner distribution | B17: =B16 -> 952520.4 | C17: =B17+C16 -> 1952666.8 | D17: =C17+D16 -> 3002820.6 | E17: =D17+E16 -> 4105482 | F17: =E17+F16 -> 5263276.5 | G17: =F17+G16 -> 6478960.7 | H17: =G17+H16 -> 7755429.1 | I17: =H17+I16 -> 9095721 | J17: =I17+J16 -> 10503027 | ... U17: =T17+U16 -> 31495996
A18: Partner cash yield (on total buy-in) | B18: =B16/Control!$B$15 -> 0.14883131 | C18: =C16/Control!$B$15 -> 0.15627288 | D18: =D16/Control!$B$15 -> 0.16408652 | E18: =E16/Control!$B$15 -> 0.17229085 | F18: =F16/Control!$B$15 -> 0.18090539 | G18: =G16/Control!$B$15 -> 0.18995066 | H18: =H16/Control!$B$15 -> 0.19944819 | I18: =I16/Control!$B$15 -> 0.2094206 | ... U18: =U16/Control!$B$15 -> 0.37608931
A19: Average annual cash yield (on buy-in) | B19: =AVERAGE(B18:U18) -> 0.24606247
A20: DISTRIBUTION ALLOCATION HELPER — driven by Control column C
A21: African Sky distributable cash | B21: =B10+B14 -> 1422627.6 | C21: =C10+C14 -> 1493759 | D21: =D10+D14 -> 1568446.9 | E21: =E10+E14 -> 1646869.3 | F21: =F10+F14 -> 1729212.7 | G21: =G10+G14 -> 1815673.4 | H21: =H10+H14 -> 1906457 | I21: =I10+I14 -> 2001779.9 | ... U21: =U10+U14 -> 3594909.1
A22: Beachside distributable cash | B22: =B11 -> 294248.4 | C22: =C11 -> 308960.82 | D22: =D11 -> 324408.86 | E22: =E11 -> 340629.3 | F22: =F11 -> 357660.77 | G22: =G11 -> 375543.81 | H22: =H11 -> 394321 | I22: =I11 -> 414037.05 | ... U22: =U11 -> 743551.05
A23: Menlyn distributable cash | B23: =B12 -> 188164.8 | C23: =C12 -> 197573.04 | D23: =D12 -> 207451.69 | E23: =E12 -> 217824.28 | F23: =F12 -> 228715.49 | G23: =G12 -> 240151.26 | H23: =H12 -> 252158.83 | I23: =I12 -> 264766.77 | ... U23: =U12 -> 475483.08
A24: African Sky partner distribution | B24: =B21*Control!$C$5 -> 711313.8 | C24: =C21*Control!$C$5 -> 746879.49 | D24: =D21*Control!$C$5 -> 784223.46 | E24: =E21*Control!$C$5 -> 823434.63 | F24: =F21*Control!$C$5 -> 864606.37 | G24: =G21*Control!$C$5 -> 907836.68 | H24: =H21*Control!$C$5 -> 953228.52 | I24: =I21*Control!$C$5 -> 1000889.9 | ... U24: =U21*Control!$C$5 -> 1797454.5
A25: Beachside partner distribution | B25: =B22*Control!$C$7 -> 147124.2 | C25: =C22*Control!$C$7 -> 154480.41 | D25: =D22*Control!$C$7 -> 162204.43 | E25: =E22*Control!$C$7 -> 170314.65 | F25: =F22*Control!$C$7 -> 178830.38 | G25: =G22*Control!$C$7 -> 187771.9 | H25: =H22*Control!$C$7 -> 197160.5 | I25: =I22*Control!$C$7 -> 207018.52 | ... U25: =U22*Control!$C$7 -> 371775.53
A26: Menlyn partner distribution | B26: =B23*Control!$C$8 -> 94082.4 | C26: =C23*Control!$C$8 -> 98786.52 | D26: =D23*Control!$C$8 -> 103725.85 | E26: =E23*Control!$C$8 -> 108912.14 | F26: =F23*Control!$C$8 -> 114357.75 | G26: =G23*Control!$C$8 -> 120075.63 | H26: =H23*Control!$C$8 -> 126079.41 | I26: =I23*Control!$C$8 -> 132383.38 | ... U26: =U23*Control!$C$8 -> 237741.54
A27: African Sky cumulative distribution | B27: =B24 -> 711313.8 | C27: =B27+C24 -> 1458193.3 | D27: =C27+D24 -> 2242416.7 | E27: =D27+E24 -> 3065851.4 | F27: =E27+F24 -> 3930457.7 | G27: =F27+G24 -> 4838294.4 | H27: =G27+H24 -> 5791523 | I27: =H27+I24 -> 6792412.9 | J27: =I27+J24 -> 7843347.3 | ... U27: =T27+U24 -> 23520269
A28: Beachside cumulative distribution | B28: =B25 -> 147124.2 | C28: =B28+C25 -> 301604.61 | D28: =C28+D25 -> 463809.04 | E28: =D28+E25 -> 634123.69 | F28: =E28+F25 -> 812954.08 | G28: =F28+G25 -> 1000726 | H28: =G28+H25 -> 1197886.5 | I28: =H28+I25 -> 1404905 | J28: =I28+J25 -> 1622274.5 | ... U28: =T28+U25 -> 4864802
A29: Menlyn cumulative distribution | B29: =B26 -> 94082.4 | C29: =B29+C26 -> 192868.92 | D29: =C29+D26 -> 296594.77 | E29: =D29+E26 -> 405506.9 | F29: =E29+F26 -> 519864.65 | G29: =F29+G26 -> 639940.28 | H29: =G29+H26 -> 766019.7 | I29: =H29+I26 -> 898403.08 | J29: =I29+J26 -> 1037405.6 | ... U29: =T29+U26 -> 3110924.3

Sheet INV - Property Breakdown
A1: PROPERTY OVERVIEW + PROPERTY-SPECIFIC PARTNER ECONOMICS
A2: Scenario share inputs include/exclude each property: 0% excludes, >0% includes at selected partner share. Winchester follows African Sky and its expansion option.
A4: TABLE 1 — PROPERTY / ASSET METRICS
A5: Metric | B5: African Sky Villas | C5: Beachside Escape | D5: Menlyn Main | E5: Portfolio
A6: Description | B6: 3-villa short-let / hospitality asset: African Sky Villa, Remington Villa and planned Winchester, with meals plus tours & activities. | C6: Big Bay property with mixed long-term rental plus peak holiday letting during Dec/Jan. | D6: Long-term residential rental apartment with recurring monthly rental income. | E6: Combined NewCo property portfolio.
A7: Revenue basis | B7: Accommodation + meals + tours & activities. | C7: 10 months long-term rent + 2 peak holiday months. | D7: Monthly long-term rental. | E7: All property revenue streams consolidated.
A8: Adopted property value (100%) | B8: =Valuation!C9 -> 6000000 | C8: =Valuation!D9 -> 4000000 | D8: =Valuation!E9 -> 2900000 | E8: =Valuation!F9 -> 12900000
A9: Year 1 NOI | B9: ='Portfolio NewCo'!B6 -> 1948804.9 | C9: ='Portfolio NewCo'!B7 -> 403080 | D9: ='Portfolio NewCo'!B8 -> 257760 | E9: ='Portfolio NewCo'!B9 -> 2609644.9
A10: NOI yield on adopted value | B10: ='INV - Property KPIs'!B9 -> 0.34131153 | C10: ='INV - Property KPIs'!C9 -> 0.10589247 | D10: ='INV - Property KPIs'!D9 -> 0.093400966 | E10: ='INV - Property KPIs'!F9 -> 0.21258154
